<?xml version="1.0"?>
<robot xmlns:xacro="http://www.ros.org/wiki/xacro" >
    <xacro:include filename="inertial_macros.xacro"/>
    <!-- <xacro:include filename="materials.xacro"/> -->


    <material name="white">
        <color rgba="1 1 1 1" />
    </material>

    <material name="orange">
        <color rgba="1 0.3 0.1 1"/>
    </material>

    <material name="blue">
        <color rgba="0.2 0.2 1 1"/>
    </material>

    <material name="black">
        <color rgba="0 0 0 1"/>
    </material>
    <material name="red">
        <color rgba="1 0 0 1"/>
    </material>
    <material name="yellow">
        <color rgba="0.8 0.8 0 1"/>
    </material>
    <material name="dark_gray">
        <color rgba="0.5 0.5 0.5 1"/>
    </material>

    <!-- BASE LINK -->

    <link name="base_link">

    </link>


    <!-- CHASSIS LINK -->

    <joint name="chassis_joint" type="fixed">
        <parent link="base_link"/>
        <child link="chassis_link"/>
        <origin xyz="-0.65 0 0"/>
    </joint>

    <link name="chassis_link">
        <visual>
            <origin xyz="0.65 0 0.415"/>
            <geometry>
                <box size="1.3 0.94 0.83"/>
            </geometry>
            <material name="orange"/>
        </visual>
        <xacro:inertial_box mass="0.5" x="1.3" y="0.94" z="0.83">
            <origin xyz="0.65 0 0.415"/>
        </xacro:inertial_box>
    </link>
    <gazebo reference="chassis_link">
        <material>Gazebo/Orange</material>
    </gazebo>


    <!-- Back LEFT WHEEL LINK -->

    <joint name="back_left_wheel_joint" type="continuous">
        <parent link="chassis_link"/>
        <child link="back_left_wheel"/>
        <origin xyz="0 0.525 0" rpy="-${pi/2} 0 0" />
        <axis xyz="0 0 1"/>
    </joint>

    <link name="back_left_wheel">
        <visual>
            <geometry>
                <cylinder radius="0.1397" length="0.125"/>
            </geometry>
            <material name="blue"/>
        </visual>
        <collision>
            <geometry>
                <cylinder radius="0.1397" length="0.125"/>
            </geometry>
        </collision>
        <xacro:inertial_cylinder mass="0.1" length="0.1397" radius="0.125">
            <origin xyz="0 0 0" rpy="0 0 0"/>
        </xacro:inertial_cylinder>
    </link>
    <gazebo reference="back_left_wheel">
        <material>Gazebo/Blue</material>
    </gazebo>

    <!-- Back RIGHT WHEEL LINK -->

    <joint name="back_right_wheel_joint" type="continuous">
        <parent link="chassis_link"/>
        <child link="back_right_wheel"/>
        <origin xyz="0 -0.525 0" rpy="${pi/2} 0 0" />
        <axis xyz="0 0 -1"/>
    </joint>

    <link name="back_right_wheel">
        <visual>
            <geometry>
                <cylinder radius="0.1397" length="0.125"/>
            </geometry>
            <material name="blue"/>
        </visual>
        <collision>
            <geometry>
                <cylinder radius="0.1397" length="0.125"/>
            </geometry>
        </collision>
        <xacro:inertial_cylinder mass="0.1" length="0.1397" radius="0.125">
            <origin xyz="0 0 0" rpy="0 0 0"/>
        </xacro:inertial_cylinder>
    </link>
    <gazebo reference="back_right_wheel">
        <material>Gazebo/Blue</material>
    </gazebo>

    <!-- Steer LINK -->

    <!-- Front LEFT WHEEL LINK -->

    <joint name="front_left_wheel_joint" type="continuous">
        <parent link="chassis_link"/>
        <child link="front_left_wheel"/>
        <origin xyz="1.3 0.525 0" rpy="-${pi/2} 0 0" />
        <axis xyz="0 0 1"/>
    </joint>

    <link name="front_left_wheel">
        <visual>
            <geometry>
                <cylinder radius="0.1397" length="0.125"/>
            </geometry>
            <material name="blue"/>
        </visual>
        <collision>
            <geometry>
                <cylinder radius="0.1397" length="0.125"/>
            </geometry>
        </collision>
        <xacro:inertial_cylinder mass="0.1" length="0.1397" radius="0.125">
            <origin xyz="0 0 0" rpy="0 0 0"/>
        </xacro:inertial_cylinder>
    </link>
    <gazebo reference="front_left_wheel">
        <material>Gazebo/Blue</material>
    </gazebo>

    <!-- RIGHT WHEEL LINK -->

    <joint name="front_right_wheel_joint" type="continuous">
        <parent link="chassis_link"/>
        <child link="front_right_wheel"/>
        <origin xyz="1.3 -0.525 0" rpy="${pi/2} 0 0" />
        <axis xyz="0 0 -1"/>
    </joint>

    <link name="front_right_wheel">
        <visual>
            <geometry>
                <cylinder radius="0.1397" length="0.125"/>
            </geometry>
            <material name="blue"/>
        </visual>
        <collision>
            <geometry>
                <cylinder radius="0.1397" length="0.125"/>
            </geometry>
        </collision>
        <xacro:inertial_cylinder mass="0.1" length="0.1397" radius="0.125">
            <origin xyz="0 0 0" rpy="0 0 0"/>
        </xacro:inertial_cylinder>
    </link>
    <gazebo reference="front_right_wheel">
        <material>Gazebo/Blue</material>
    </gazebo>
    <gazebo>
        <plugin name="skid_steer_drive_controller" filename="libgazebo_ros_skid_steer_drive.so">
            <updateRate>100.0</updateRate>
            <robotNamespace>/</robotNamespace>
            <leftFrontJoint>front_left_wheel_joint</leftFrontJoint>
            <rightFrontJoint>front_right_wheel_joint</rightFrontJoint>
            <leftRearJoint>rear_left_wheel_joint</leftRearJoint>
            <rightRearJoint>rear_right_wheel_joint</rightRearJoint>
            <wheelSeparation>1.05</wheelSeparation>
            <wheelDiameter>0.2794</wheelDiameter>
            <robotBaseFrame>base_link</robotBaseFrame>
            <torque>200</torque>
            <MaxForce>5.0</MaxForce>
            <commandTopic>cmd_vel</commandTopic>
            <odometryTopic>odom</odometryTopic>
            <odometryFrame>odom</odometryFrame>
            <broadcastTF>true</broadcastTF>
            <covariance_x>0.001</covariance_x> <!-- 0.0001 -->
            <covariance_y>0.001</covariance_y> <!-- 0.0001 -->
            <covariance_yaw>0.01</covariance_yaw> <!-- 0.01 -->
        </plugin>
        

    </gazebo>


    


</robot>